2021-04-25 16:33:55,653 (datapublisher-4.0.0 5744) volttron.platform.vip.agent.subsystems.configstore DEBUG: Processing callbacks for affected files: {'config': 'NEW', 'test.csv': 'NEW', 'line_marker': 'NEW'}
2021-04-25 16:33:55,653 (datapublisher-4.0.0 5744) __main__ INFO: Config Data: {'use_timestamp': True, 'publish_interval': 1, 'base_path': 'devices/building/campus', 'input_data': '/home/suba/Desktop/volttron/examples/DataPublisher/test.csv', 'unittype_map': {'.*Temperature': 'Farenheit', '.*SetPoint': 'Farenheit', 'OutdoorDamperSignal': 'On/Off', 'SupplyFanStatus': 'On/Off', 'CoolingCall': 'On/Off', 'SupplyFanSpeed': 'RPM', 'Damper*.': 'On/Off', 'Heating*.': 'On/Off', 'DuctStatic*.': 'On/Off'}, 'replay_data': False, 'max_data_frequency': 900, 'remember_playback': True, 'reset_playback': False, 'topic_separator': '/', 'basepath': 'devices/building/campus'}
2021-04-25 16:33:57,210 (sqlhistorianagent-3.7.0 5724) volttron.platform.dbutils.sqlitefuncts DEBUG: Managing store - timestamp limit: None  GB size limit: None
2021-04-25 16:33:57,218 (sqlhistorianagent-3.7.0 5724) <stderr> ERROR: Exception in thread Thread-1:
2021-04-25 16:33:57,218 (sqlhistorianagent-3.7.0 5724) <stderr> ERROR: Traceback (most recent call last):
2021-04-25 16:33:57,218 (sqlhistorianagent-3.7.0 5724) <stderr> ERROR:   File "/usr/lib/python3.8/threading.py", line 932, in _bootstrap_inner
2021-04-25 16:33:57,218 (sqlhistorianagent-3.7.0 5724) <stderr> ERROR:     self.run()
2021-04-25 16:33:57,218 (sqlhistorianagent-3.7.0 5724) <stderr> ERROR:   File "/usr/lib/python3.8/threading.py", line 870, in run
2021-04-25 16:33:57,219 (sqlhistorianagent-3.7.0 5724) <stderr> ERROR:     self._target(*self._args, **self._kwargs)
2021-04-25 16:33:57,219 (sqlhistorianagent-3.7.0 5724) <stderr> ERROR:   File "/home/suba/Desktop/volttron/volttron/platform/agent/base_historian.py", line 1101, in _process_loop
2021-04-25 16:33:57,219 (sqlhistorianagent-3.7.0 5724) <stderr> ERROR:     self._do_process_loop()
2021-04-25 16:33:57,220 (sqlhistorianagent-3.7.0 5724) <stderr> ERROR:   File "/home/suba/Desktop/volttron/volttron/platform/agent/base_historian.py", line 1159, in _do_process_loop
2021-04-25 16:33:57,220 (sqlhistorianagent-3.7.0 5724) <stderr> ERROR:     cache_full = backupdb.backup_new_data(new_to_publish, bool(self._time_tolerance))
2021-04-25 16:33:57,220 (sqlhistorianagent-3.7.0 5724) <stderr> ERROR:   File "/home/suba/Desktop/volttron/volttron/platform/agent/base_historian.py", line 1516, in backup_new_data
2021-04-25 16:33:57,220 (sqlhistorianagent-3.7.0 5724) <stderr> ERROR:     c.execute('''INSERT OR REPLACE INTO metadata
2021-04-25 16:33:57,220 (sqlhistorianagent-3.7.0 5724) <stderr> ERROR: sqlite3.InterfaceError: Error binding parameter 3 - probably unsupported type.

